Workbook

Sheet Total Score
B2: Final Score (out of 100)
A3: # | B3: Company | C3: Growth Score | D3: Return Score | E3: Leverage Score | F3: Valuation Score | G3: Total Score = Growth Score * 0.25 + Return Score * 0.25 + Leverage Score * 0.25 + Valuation Score * 0.25
B4: LTIMINDTREE LTD | C4: ='Percentile Ranking'!C120/3+'Percentile Ranking'!D120/3+'Percentile Ranking'!E120/3 -> 0.856 | D4: ='Percentile Ranking'!F120*0.25+'Percentile Ranking'!G120*0.25+'Percentile Ranking'!H120*0.25+'Percentile Ranking'!I120*0.25 -> 0.901 | E4: ='Percentile Ranking'!J120/3 + 'Percentile Ranking'!K120/3 + 'Percentile Ranking'!L120/3 -> 0.70333333 | F4: ='Percentile Ranking'!M120/3 + 'Percentile Ranking'!N120/3 + 'Percentile Ranking'!O120/3 -> 0.67833333 | G4: =C4 * 0.25 + D4 * 0.25 + E4 * 0.25 + F4 * 0.25 -> 0.78466667
B5: NATIONAL ALUMINIUM COMPANY LTD | C5: ='Percentile Ranking'!C134/3+'Percentile Ranking'!D134/3+'Percentile Ranking'!E134/3 -> 0.754 | D5: ='Percentile Ranking'!F134*0.25+'Percentile Ranking'!G134*0.25+'Percentile Ranking'!H134*0.25+'Percentile Ranking'!I134*0.25 -> 0.632 | E5: ='Percentile Ranking'!J134/3 + 'Percentile Ranking'!K134/3 + 'Percentile Ranking'!L134/3 -> 0.903 | F5: ='Percentile Ranking'!M134/3 + 'Percentile Ranking'!N134/3 + 'Percentile Ranking'!O134/3 -> 0.846 | G5: =C5 * 0.25 + D5 * 0.25 + E5 * 0.25 + F5 * 0.25 -> 0.78375
B6: INDRAPRASTHA GAS LTD | C6: ='Percentile Ranking'!C97/3+'Percentile Ranking'!D97/3+'Percentile Ranking'!E97/3 -> 0.638 | D6: ='Percentile Ranking'!F97*0.25+'Percentile Ranking'!G97*0.25+'Percentile Ranking'!H97*0.25+'Percentile Ranking'!I97*0.25 -> 0.78275 | E6: ='Percentile Ranking'!J97/3 + 'Percentile Ranking'!K97/3 + 'Percentile Ranking'!L97/3 -> 0.859 | F6: ='Percentile Ranking'!M97/3 + 'Percentile Ranking'!N97/3 + 'Percentile Ranking'!O97/3 -> 0.789 | G6: =C6 * 0.25 + D6 * 0.25 + E6 * 0.25 + F6 * 0.25 -> 0.7671875
B7: TATA ELXSI LTD | C7: ='Percentile Ranking'!C180/3+'Percentile Ranking'!D180/3+'Percentile Ranking'!E180/3 -> 0.73066667 | D7: ='Percentile Ranking'!F180*0.25+'Percentile Ranking'!G180*0.25+'Percentile Ranking'!H180*0.25+'Percentile Ranking'!I180*0.25 -> 0.8985 | E7: ='Percentile Ranking'!J180/3 + 'Percentile Ranking'!K180/3 + 'Percentile Ranking'!L180/3 -> 0.76066667 | F7: ='Percentile Ranking'!M180/3 + 'Percentile Ranking'!N180/3 + 'Percentile Ranking'!O180/3 -> 0.54933333 | G7: =C7 * 0.25 + D7 * 0.25 + E7 * 0.25 + F7 * 0.25 -> 0.73479167
B8: NMDC LTD | C8: ='Percentile Ranking'!C137/3+'Percentile Ranking'!D137/3+'Percentile Ranking'!E137/3 -> 0.608 | D8: ='Percentile Ranking'!F137*0.25+'Percentile Ranking'!G137*0.25+'Percentile Ranking'!H137*0.25+'Percentile Ranking'!I137*0.25 -> 0.7675 | E8: ='Percentile Ranking'!J137/3 + 'Percentile Ranking'!K137/3 + 'Percentile Ranking'!L137/3 -> 0.75833333 | F8: ='Percentile Ranking'!M137/3 + 'Percentile Ranking'!N137/3 + 'Percentile Ranking'!O137/3 -> 0.78233333 | G8: =C8 * 0.25 + D8 * 0.25 + E8 * 0.25 + F8 * 0.25 -> 0.72904167
B9: SUPREME INDUSTRIES LTD | C9: ='Percentile Ranking'!C174/3+'Percentile Ranking'!D174/3+'Percentile Ranking'!E174/3 -> 0.68366667 | D9: ='Percentile Ranking'!F174*0.25+'Percentile Ranking'!G174*0.25+'Percentile Ranking'!H174*0.25+'Percentile Ranking'!I174*0.25 -> 0.869 | E9: ='Percentile Ranking'!J174/3 + 'Percentile Ranking'!K174/3 + 'Percentile Ranking'!L174/3 -> 0.72533333 | F9: ='Percentile Ranking'!M174/3 + 'Percentile Ranking'!N174/3 + 'Percentile Ranking'!O174/3 -> 0.56433333 | G9: =C9 * 0.25 + D9 * 0.25 + E9 * 0.25 + F9 * 0.25 -> 0.71058333
B10: HDFC ASSET MANAGEMENT COMPANY LTD | C10: ='Percentile Ranking'!C76/3+'Percentile Ranking'!D76/3+'Percentile Ranking'!E76/3 -> 0.70366667 | D10: ='Percentile Ranking'!F76*0.25+'Percentile Ranking'!G76*0.25+'Percentile Ranking'!H76*0.25+'Percentile Ranking'!I76*0.25 -> 0.80175 | E10: ='Percentile Ranking'!J76/3 + 'Percentile Ranking'!K76/3 + 'Percentile Ranking'!L76/3 -> 0.933 | F10: ='Percentile Ranking'!M76/3 + 'Percentile Ranking'!N76/3 + 'Percentile Ranking'!O76/3 -> 0.39366667 | G10: =C10 * 0.25 + D10 * 0.25 + E10 * 0.25 + F10 * 0.25 -> 0.70802083
B11: INDUS TOWERS LTD | C11: ='Percentile Ranking'!C98/3+'Percentile Ranking'!D98/3+'Percentile Ranking'!E98/3 -> 0.88766667 | D11: ='Percentile Ranking'!F98*0.25+'Percentile Ranking'!G98*0.25+'Percentile Ranking'!H98*0.25+'Percentile Ranking'!I98*0.25 -> 0.642 | E11: ='Percentile Ranking'!J98/3 + 'Percentile Ranking'!K98/3 + 'Percentile Ranking'!L98/3 -> 0.48233333 | F11: ='Percentile Ranking'!M98/3 + 'Percentile Ranking'!N98/3 + 'Percentile Ranking'!O98/3 -> 0.80066667 | G11: =C11 * 0.25 + D11 * 0.25 + E11 * 0.25 + F11 * 0.25 -> 0.70316667
B12: INFOSYS LTD | C12: ='Percentile Ranking'!C101/3+'Percentile Ranking'!D101/3+'Percentile Ranking'!E101/3 -> 0.44733333 | D12: ='Percentile Ranking'!F101*0.25+'Percentile Ranking'!G101*0.25+'Percentile Ranking'!H101*0.25+'Percentile Ranking'!I101*0.25 -> 0.88225 | E12: ='Percentile Ranking'!J101/3 + 'Percentile Ranking'!K101/3 + 'Percentile Ranking'!L101/3 -> 0.799 | F12: ='Percentile Ranking'!M101/3 + 'Percentile Ranking'!N101/3 + 'Percentile Ranking'!O101/3 -> 0.65633333 | G12: =C12 * 0.25 + D12 * 0.25 + E12 * 0.25 + F12 * 0.25 -> 0.69622917
B13: INFO EDGE (INDIA) LTD | C13: ='Percentile Ranking'!C100/3+'Percentile Ranking'!D100/3+'Percentile Ranking'!E100/3 -> 0.82766667 | D13: ='Percentile Ranking'!F100*0.25+'Percentile Ranking'!G100*0.25+'Percentile Ranking'!H100*0.25+'Percentile Ranking'!I100*0.25 -> 0.466 | E13: ='Percentile Ranking'!J100/3 + 'Percentile Ranking'!K100/3 + 'Percentile Ranking'!L100/3 -> 0.83066667 | F13: ='Percentile Ranking'!M100/3 + 'Percentile Ranking'!N100/3 + 'Percentile Ranking'!O100/3 -> 0.59333333 | G13: =C13 * 0.25 + D13 * 0.25 + E13 * 0.25 + F13 * 0.25 -> 0.67941667
B14: PERSISTENT SYSTEMS LTD | C14: ='Percentile Ranking'!C149/3+'Percentile Ranking'!D149/3+'Percentile Ranking'!E149/3 -> 0.82433333 | D14: ='Percentile Ranking'!F149*0.25+'Percentile Ranking'!G149*0.25+'Percentile Ranking'!H149*0.25+'Percentile Ranking'!I149*0.25 -> 0.81275 | E14: ='Percentile Ranking'!J149/3 + 'Percentile Ranking'!K149/3 + 'Percentile Ranking'!L149/3 -> 0.881 | F14: ='Percentile Ranking'!M149/3 + 'Percentile Ranking'!N149/3 + 'Percentile Ranking'!O149/3 -> 0.17433333 | G14: =C14 * 0.25 + D14 * 0.25 + E14 * 0.25 + F14 * 0.25 -> 0.67310417
B15: BHARAT ELECTRONICS LTD | C15: ='Percentile Ranking'!C34/3+'Percentile Ranking'!D34/3+'Percentile Ranking'!E34/3 -> 0.725 | D15: ='Percentile Ranking'!F34*0.25+'Percentile Ranking'!G34*0.25+'Percentile Ranking'!H34*0.25+'Percentile Ranking'!I34*0.25 -> 0.682 | E15: ='Percentile Ranking'!J34/3 + 'Percentile Ranking'!K34/3 + 'Percentile Ranking'!L34/3 -> 0.913 | F15: ='Percentile Ranking'!M34/3 + 'Percentile Ranking'!N34/3 + 'Percentile Ranking'!O34/3 -> 0.36166667 | G15: =C15 * 0.25 + D15 * 0.25 + E15 * 0.25 + F15 * 0.25 -> 0.67041667
B16: ORACLE FINANCIAL SERVICES SOFTWARE LTD | C16: ='Percentile Ranking'!C144/3+'Percentile Ranking'!D144/3+'Percentile Ranking'!E144/3 -> 0.41033333 | D16: ='Percentile Ranking'!F144*0.25+'Percentile Ranking'!G144*0.25+'Percentile Ranking'!H144*0.25+'Percentile Ranking'!I144*0.25 -> 0.84425 | E16: ='Percentile Ranking'!J144/3 + 'Percentile Ranking'!K144/3 + 'Percentile Ranking'!L144/3 -> 0.923 | F16: ='Percentile Ranking'!M144/3 + 'Percentile Ranking'!N144/3 + 'Percentile Ranking'!O144/3 -> 0.50266667 | G16: =C16 * 0.25 + D16 * 0.25 + E16 * 0.25 + F16 * 0.25 -> 0.6700625
B17: HERO MOTOCORP LTD | C17: ='Percentile Ranking'!C79/3+'Percentile Ranking'!D79/3+'Percentile Ranking'!E79/3 -> 0.253 | D17: ='Percentile Ranking'!F79*0.25+'Percentile Ranking'!G79*0.25+'Percentile Ranking'!H79*0.25+'Percentile Ranking'!I79*0.25 -> 0.879 | E17: ='Percentile Ranking'!J79/3 + 'Percentile Ranking'!K79/3 + 'Percentile Ranking'!L79/3 -> 0.89433333 | F17: ='Percentile Ranking'!M79/3 + 'Percentile Ranking'!N79/3 + 'Percentile Ranking'!O79/3 -> 0.648 | G17: =C17 * 0.25 + D17 * 0.25 + E17 * 0.25 + F17 * 0.25 -> 0.66858333
B18: P I INDUSTRIES LTD | C18: ='Percentile Ranking'!C145/3+'Percentile Ranking'!D145/3+'Percentile Ranking'!E145/3 -> 0.79233333 | D18: ='Percentile Ranking'!F145*0.25+'Percentile Ranking'!G145*0.25+'Percentile Ranking'!H145*0.25+'Percentile Ranking'!I145*0.25 -> 0.69975 | E18: ='Percentile Ranking'!J145/3 + 'Percentile Ranking'!K145/3 + 'Percentile Ranking'!L145/3 -> 0.727 | F18: ='Percentile Ranking'!M145/3 + 'Percentile Ranking'!N145/3 + 'Percentile Ranking'!O145/3 -> 0.45233333 | G18: =C18 * 0.25 + D18 * 0.25 + E18 * 0.25 + F18 * 0.25 -> 0.66785417
B19: INDIAN RAILWAY CATERING & TOURISM CORPORATION LTD | C19: ='Percentile Ranking'!C94/3+'Percentile Ranking'!D94/3+'Percentile Ranking'!E94/3 -> 0.81933333 | D19: ='Percentile Ranking'!F94*0.25+'Percentile Ranking'!G94*0.25+'Percentile Ranking'!H94*0.25+'Percentile Ranking'!I94*0.25 -> 0.81425 | E19: ='Percentile Ranking'!J94/3 + 'Percentile Ranking'!K94/3 + 'Percentile Ranking'!L94/3 -> 0.78233333 | F19: ='Percentile Ranking'!M94/3 + 'Percentile Ranking'!N94/3 + 'Percentile Ranking'!O94/3 -> 0.253 | G19: =C19 * 0.25 + D19 * 0.25 + E19 * 0.25 + F19 * 0.25 -> 0.66722917
B20: ITC LTD | C20: ='Percentile Ranking'!C105/3+'Percentile Ranking'!D105/3+'Percentile Ranking'!E105/3 -> 0.43233333 | D20: ='Percentile Ranking'!F105*0.25+'Percentile Ranking'!G105*0.25+'Percentile Ranking'!H105*0.25+'Percentile Ranking'!I105*0.25 -> 0.76375 | E20: ='Percentile Ranking'!J105/3 + 'Percentile Ranking'!K105/3 + 'Percentile Ranking'!L105/3 -> 0.92633333 | F20: ='Percentile Ranking'!M105/3 + 'Percentile Ranking'!N105/3 + 'Percentile Ranking'!O105/3 -> 0.54266667 | G20: =C20 * 0.25 + D20 * 0.25 + E20 * 0.25 + F20 * 0.25 -> 0.66627083
B21: HCL TECHNOLOGIES LTD | C21: ='Percentile Ranking'!C75/3+'Percentile Ranking'!D75/3+'Percentile Ranking'!E75/3 -> 0.643 | D21: ='Percentile Ranking'!F75*0.25+'Percentile Ranking'!G75*0.25+'Percentile Ranking'!H75*0.25+'Percentile Ranking'!I75*0.25 -> 0.87925 | E21: ='Percentile Ranking'!J75/3 + 'Percentile Ranking'!K75/3 + 'Percentile Ranking'!L75/3 -> 0.854 | F21: ='Percentile Ranking'!M75/3 + 'Percentile Ranking'!N75/3 + 'Percentile Ranking'!O75/3 -> 0.27466667 | G21: =C21 * 0.25 + D21 * 0.25 + E21 * 0.25 + F21 * 0.25 -> 0.66272917
B22: EICHER MOTORS LTD | C22: ='Percentile Ranking'!C61/3+'Percentile Ranking'!D61/3+'Percentile Ranking'!E61/3 -> 0.58633333 | D22: ='Percentile Ranking'!F61*0.25+'Percentile Ranking'!G61*0.25+'Percentile Ranking'!H61*0.25+'Percentile Ranking'!I61*0.25 -> 0.809 | E22: ='Percentile Ranking'!J61/3 + 'Percentile Ranking'!K61/3 + 'Percentile Ranking'!L61/3 -> 0.89266667 | F22: ='Percentile Ranking'!M61/3 + 'Percentile Ranking'!N61/3 + 'Percentile Ranking'!O61/3 -> 0.355 | G22: =C22 * 0.25 + D22 * 0.25 + E22 * 0.25 + F22 * 0.25 -> 0.66075
B23: GAIL (INDIA) LTD | C23: ='Percentile Ranking'!C67/3+'Percentile Ranking'!D67/3+'Percentile Ranking'!E67/3 -> 0.64666667 | D23: ='Percentile Ranking'!F67*0.25+'Percentile Ranking'!G67*0.25+'Percentile Ranking'!H67*0.25+'Percentile Ranking'!I67*0.25 -> 0.6105 | E23: ='Percentile Ranking'!J67/3 + 'Percentile Ranking'!K67/3 + 'Percentile Ranking'!L67/3 -> 0.57633333 | F23: ='Percentile Ranking'!M67/3 + 'Percentile Ranking'!N67/3 + 'Percentile Ranking'!O67/3 -> 0.79733333 | G23: =C23 * 0.25 + D23 * 0.25 + E23 * 0.25 + F23 * 0.25 -> 0.65770833
B24: POLYCAB INDIA LTD | C24: ='Percentile Ranking'!C152/3+'Percentile Ranking'!D152/3+'Percentile Ranking'!E152/3 -> 0.86933333 | D24: ='Percentile Ranking'!F152*0.25+'Percentile Ranking'!G152*0.25+'Percentile Ranking'!H152*0.25+'Percentile Ranking'!I152*0.25 -> 0.8055 | E24: ='Percentile Ranking'!J152/3 + 'Percentile Ranking'!K152/3 + 'Percentile Ranking'!L152/3 -> 0.59966667 | F24: ='Percentile Ranking'!M152/3 + 'Percentile Ranking'!N152/3 + 'Percentile Ranking'!O152/3 -> 0.35366667 | G24: =C24 * 0.25 + D24 * 0.25 + E24 * 0.25 + F24 * 0.25 -> 0.65704167
B25: BSE LTD | C25: ='Percentile Ranking'!C44/3+'Percentile Ranking'!D44/3+'Percentile Ranking'!E44/3 -> 0.898 | D25: ='Percentile Ranking'!F44*0.25+'Percentile Ranking'!G44*0.25+'Percentile Ranking'!H44*0.25+'Percentile Ranking'!I44*0.25 -> 0.52025 | E25: ='Percentile Ranking'!J44/3 + 'Percentile Ranking'!K44/3 + 'Percentile Ranking'!L44/3 -> 0.95466667 | F25: ='Percentile Ranking'!M44/3 + 'Percentile Ranking'!N44/3 + 'Percentile Ranking'!O44/3 -> 0.248 | G25: =C25 * 0.25 + D25 * 0.25 + E25 * 0.25 + F25 * 0.25 -> 0.65522917
B26: MPHASIS LTD | C26: ='Percentile Ranking'!C131/3+'Percentile Ranking'!D131/3+'Percentile Ranking'!E131/3 -> 0.66833333 | D26: ='Percentile Ranking'!F131*0.25+'Percentile Ranking'!G131*0.25+'Percentile Ranking'!H131*0.25+'Percentile Ranking'!I131*0.25 -> 0.83925 | E26: ='Percentile Ranking'!J131/3 + 'Percentile Ranking'!K131/3 + 'Percentile Ranking'!L131/3 -> 0.75733333 | F26: ='Percentile Ranking'!M131/3 + 'Percentile Ranking'!N131/3 + 'Percentile Ranking'!O131/3 -> 0.352 | G26: =C26 * 0.25 + D26 * 0.25 + E26 * 0.25 + F26 * 0.25 -> 0.65422917
B27: TATA STEEL LTD | C27: ='Percentile Ranking'!C183/3+'Percentile Ranking'!D183/3+'Percentile Ranking'!E183/3 -> 0.79266667 | D27: ='Percentile Ranking'!F183*0.25+'Percentile Ranking'!G183*0.25+'Percentile Ranking'!H183*0.25+'Percentile Ranking'!I183*0.25 -> 0.52025 | E27: ='Percentile Ranking'!J183/3 + 'Percentile Ranking'!K183/3 + 'Percentile Ranking'!L183/3 -> 0.39866667 | F27: ='Percentile Ranking'!M183/3 + 'Percentile Ranking'!N183/3 + 'Percentile Ranking'!O183/3 -> 0.871 | G27: =C27 * 0.25 + D27 * 0.25 + E27 * 0.25 + F27 * 0.25 -> 0.64564583
B28: ASIAN PAINTS LTD | C28: ='Percentile Ranking'!C20/3+'Percentile Ranking'!D20/3+'Percentile Ranking'!E20/3 -> 0.47066667 | D28: ='Percentile Ranking'!F20*0.25+'Percentile Ranking'!G20*0.25+'Percentile Ranking'!H20*0.25+'Percentile Ranking'!I20*0.25 -> 0.8615 | E28: ='Percentile Ranking'!J20/3 + 'Percentile Ranking'!K20/3 + 'Percentile Ranking'!L20/3 -> 0.76066667 | F28: ='Percentile Ranking'!M20/3 + 'Percentile Ranking'!N20/3 + 'Percentile Ranking'!O20/3 -> 0.46066667 | G28: =C28 * 0.25 + D28 * 0.25 + E28 * 0.25 + F28 * 0.25 -> 0.638375
B29: BAJAJ AUTO LTD | C29: ='Percentile Ranking'!C26/3+'Percentile Ranking'!D26/3+'Percentile Ranking'!E26/3 -> 0.40866667 | D29: ='Percentile Ranking'!F26*0.25+'Percentile Ranking'!G26*0.25+'Percentile Ranking'!H26*0.25+'Percentile Ranking'!I26*0.25 -> 0.84675 | E29: ='Percentile Ranking'!J26/3 + 'Percentile Ranking'!K26/3 + 'Percentile Ranking'!L26/3 -> 0.901 | F29: ='Percentile Ranking'!M26/3 + 'Percentile Ranking'!N26/3 + 'Percentile Ranking'!O26/3 -> 0.39533333 | G29: =C29 * 0.25 + D29 * 0.25 + E29 * 0.25 + F29 * 0.25 -> 0.6379375
B30: NESTLE INDIA LTD | C30: ='Percentile Ranking'!C135/3+'Percentile Ranking'!D135/3+'Percentile Ranking'!E135/3 -> 0.50066667 | D30: ='Percentile Ranking'!F135*0.25+'Percentile Ranking'!G135*0.25+'Percentile Ranking'!H135*0.25+'Percentile Ranking'!I135*0.25 -> 0.97375 | E30: ='Percentile Ranking'!J135/3 + 'Percentile Ranking'!K135/3 + 'Percentile Ranking'!L135/3 -> 0.68166667 | F30: ='Percentile Ranking'!M135/3 + 'Percentile Ranking'!N135/3 + 'Percentile Ranking'!O135/3 -> 0.395 | G30: =C30 * 0.25 + D30 * 0.25 + E30 * 0.25 + F30 * 0.25 -> 0.63777083
B31: TATA CONSULTANCY SERVICES LTD | C31: ='Percentile Ranking'!C178/3+'Percentile Ranking'!D178/3+'Percentile Ranking'!E178/3 -> 0.45066667 | D31: ='Percentile Ranking'!F178*0.25+'Percentile Ranking'!G178*0.25+'Percentile Ranking'!H178*0.25+'Percentile Ranking'!I178*0.25 -> 0.96375 | E31: ='Percentile Ranking'!J178/3 + 'Percentile Ranking'!K178/3 + 'Percentile Ranking'!L178/3 -> 0.82766667 | F31: ='Percentile Ranking'!M178/3 + 'Percentile Ranking'!N178/3 + 'Percentile Ranking'!O178/3 -> 0.29633333 | G31: =C31 * 0.25 + D31 * 0.25 + E31 * 0.25 + F31 * 0.25 -> 0.63460417
B32: MOTILAL OSWAL FINANCIAL SERVICES LTD | C32: ='Percentile Ranking'!C130/3+'Percentile Ranking'!D130/3+'Percentile Ranking'!E130/3 -> 0.99 | D32: ='Percentile Ranking'!F130*0.25+'Percentile Ranking'!G130*0.25+'Percentile Ranking'!H130*0.25+'Percentile Ranking'!I130*0.25 -> 0.45575 | E32: ='Percentile Ranking'!J130/3 + 'Percentile Ranking'!K130/3 + 'Percentile Ranking'!L130/3 -> 0.337 | F32: ='Percentile Ranking'!M130/3 + 'Percentile Ranking'!N130/3 + 'Percentile Ranking'!O130/3 -> 0.73866667 | G32: =C32 * 0.25 + D32 * 0.25 + E32 * 0.25 + F32 * 0.25 -> 0.63035417
B33: CIPLA LTD | C33: ='Percentile Ranking'!C48/3+'Percentile Ranking'!D48/3+'Percentile Ranking'!E48/3 -> 0.474 | D33: ='Percentile Ranking'!F48*0.25+'Percentile Ranking'!G48*0.25+'Percentile Ranking'!H48*0.25+'Percentile Ranking'!I48*0.25 -> 0.57425 | E33: ='Percentile Ranking'!J48/3 + 'Percentile Ranking'!K48/3 + 'Percentile Ranking'!L48/3 -> 0.86933333 | F33: ='Percentile Ranking'!M48/3 + 'Percentile Ranking'!N48/3 + 'Percentile Ranking'!O48/3 -> 0.601 | G33: =C33 * 0.25 + D33 * 0.25 + E33 * 0.25 + F33 * 0.25 -> 0.62964583
B34: ICICI LOMBARD GENERAL INSURANCE COMPANY LTD | C34: ='Percentile Ranking'!C89/3+'Percentile Ranking'!D89/3+'Percentile Ranking'!E89/3 -> 0.769 | D34: ='Percentile Ranking'!F89*0.25+'Percentile Ranking'!G89*0.25+'Percentile Ranking'!H89*0.25+'Percentile Ranking'!I89*0.25 -> 0.5255 | E34: ='Percentile Ranking'!J89/3 + 'Percentile Ranking'!K89/3 + 'Percentile Ranking'!L89/3 -> 0.75233333 | F34: ='Percentile Ranking'!M89/3 + 'Percentile Ranking'!N89/3 + 'Percentile Ranking'!O89/3 -> 0.46566667 | G34: =C34 * 0.25 + D34 * 0.25 + E34 * 0.25 + F34 * 0.25 -> 0.628125
B35: DR REDDYS LABORATORIES LTD | C35: ='Percentile Ranking'!C60/3+'Percentile Ranking'!D60/3+'Percentile Ranking'!E60/3 -> 0.59766667 | D35: ='Percentile Ranking'!F60*0.25+'Percentile Ranking'!G60*0.25+'Percentile Ranking'!H60*0.25+'Percentile Ranking'!I60*0.25 -> 0.56675 | E35: ='Percentile Ranking'!J60/3 + 'Percentile Ranking'!K60/3 + 'Percentile Ranking'!L60/3 -> 0.64666667 | F35: ='Percentile Ranking'!M60/3 + 'Percentile Ranking'!N60/3 + 'Percentile Ranking'!O60/3 -> 0.67166667 | G35: =C35 * 0.25 + D35 * 0.25 + E35 * 0.25 + F35 * 0.25 -> 0.6206875
B36: MAZAGON DOCK SHIPBUILDERS LTD | C36: ='Percentile Ranking'!C129/3+'Percentile Ranking'!D129/3+'Percentile Ranking'!E129/3 -> 0.75033333 | D36: ='Percentile Ranking'!F129*0.25+'Percentile Ranking'!G129*0.25+'Percentile Ranking'!H129*0.25+'Percentile Ranking'!I129*0.25 -> 0.60175 | E36: ='Percentile Ranking'!J129/3 + 'Percentile Ranking'!K129/3 + 'Percentile Ranking'!L129/3 -> 0.87266667 | F36: ='Percentile Ranking'!M129/3 + 'Percentile Ranking'!N129/3 + 'Percentile Ranking'!O129/3 -> 0.255 | G36: =C36 * 0.25 + D36 * 0.25 + E36 * 0.25 + F36 * 0.25 -> 0.6199375
B37: ASTRAL LTD | C37: ='Percentile Ranking'!C21/3+'Percentile Ranking'!D21/3+'Percentile Ranking'!E21/3 -> 0.839 | D37: ='Percentile Ranking'!F21*0.25+'Percentile Ranking'!G21*0.25+'Percentile Ranking'!H21*0.25+'Percentile Ranking'!I21*0.25 -> 0.73375 | E37: ='Percentile Ranking'!J21/3 + 'Percentile Ranking'!K21/3 + 'Percentile Ranking'!L21/3 -> 0.663 | F37: ='Percentile Ranking'!M21/3 + 'Percentile Ranking'!N21/3 + 'Percentile Ranking'!O21/3 -> 0.23766667 | G37: =C37 * 0.25 + D37 * 0.25 + E37 * 0.25 + F37 * 0.25 -> 0.61835417
B38: KEI INDUSTRIES LTD | C38: ='Percentile Ranking'!C112/3+'Percentile Ranking'!D112/3+'Percentile Ranking'!E112/3 -> 0.831 | D38: ='Percentile Ranking'!F112*0.25+'Percentile Ranking'!G112*0.25+'Percentile Ranking'!H112*0.25+'Percentile Ranking'!I112*0.25 -> 0.7665 | E38: ='Percentile Ranking'!J112/3 + 'Percentile Ranking'!K112/3 + 'Percentile Ranking'!L112/3 -> 0.442 | F38: ='Percentile Ranking'!M112/3 + 'Percentile Ranking'!N112/3 + 'Percentile Ranking'!O112/3 -> 0.42566667 | G38: =C38 * 0.25 + D38 * 0.25 + E38 * 0.25 + F38 * 0.25 -> 0.61629167
B39: TITAN COMPANY LTD | C39: ='Percentile Ranking'!C186/3+'Percentile Ranking'!D186/3+'Percentile Ranking'!E186/3 -> 0.814 | D39: ='Percentile Ranking'!F186*0.25+'Percentile Ranking'!G186*0.25+'Percentile Ranking'!H186*0.25+'Percentile Ranking'!I186*0.25 -> 0.784 | E39: ='Percentile Ranking'!J186/3 + 'Percentile Ranking'!K186/3 + 'Percentile Ranking'!L186/3 -> 0.43233333 | F39: ='Percentile Ranking'!M186/3 + 'Percentile Ranking'!N186/3 + 'Percentile Ranking'!O186/3 -> 0.43233333 | G39: =C39 * 0.25 + D39 * 0.25 + E39 * 0.25 + F39 * 0.25 -> 0.61566667
B40: AVENUE SUPERMARTS LTD | C40: ='Percentile Ranking'!C24/3+'Percentile Ranking'!D24/3+'Percentile Ranking'!E24/3 -> 0.908 | D40: ='Percentile Ranking'!F24*0.25+'Percentile Ranking'!G24*0.25+'Percentile Ranking'!H24*0.25+'Percentile Ranking'!I24*0.25 -> 0.73125 | E40: ='Percentile Ranking'!J24/3 + 'Percentile Ranking'!K24/3 + 'Percentile Ranking'!L24/3 -> 0.66633333 | F40: ='Percentile Ranking'!M24/3 + 'Percentile Ranking'!N24/3 + 'Percentile Ranking'!O24/3 -> 0.15566667 | G40: =C40 * 0.25 + D40 * 0.25 + E40 * 0.25 + F40 * 0.25 -> 0.6153125
B41: ACC LTD | C41: ='Percentile Ranking'!C7/3+'Percentile Ranking'!D7/3+'Percentile Ranking'!E7/3 -> 0.454 | D41: ='Percentile Ranking'!F7*0.25+'Percentile Ranking'!G7*0.25+'Percentile Ranking'!H7*0.25+'Percentile Ranking'!I7*0.25 -> 0.534 | E41: ='Percentile Ranking'!J7/3 + 'Percentile Ranking'!K7/3 + 'Percentile Ranking'!L7/3 -> 0.757 | F41: ='Percentile Ranking'!M7/3 + 'Percentile Ranking'!N7/3 + 'Percentile Ranking'!O7/3 -> 0.70833333 | G41: =C41 * 0.25 + D41 * 0.25 + E41 * 0.25 + F41 * 0.25 -> 0.61333333
...

Sheet Master Data
B2: Master Sheet - Raw Data
C3: Growth Metrics (0.25) | F3: Return Metrics (0.25) | J3: Leverage Metrics (0.25) | M3: Valuation Metrics (0.25)
A4: # | B4: Company | C4: 10Y Sales CAGR | D4: 10Y EBITDA CAGR | E4: 10Y Net Profit CAGR | F4: 10Y Mean ROCE | G4: 10Y Mean ROE | H4: 10Y Mean ROA | I4: Asset Turnover Ratio - Current | J4: 10Y Debt to Equity Mean | K4: 10Y Debt to EBITDA Mean | L4: 10Y Interest Coverage Ratio Mean | M4: Current EV/EBITDA Ratio | N4: Current PEG Ratio | O4: Current P/B Ratio
B5: 360 ONE WAM LTD | C5: 0.058157681 | D5: 0.13129225 | E5: 0.12458284 | F5: 0.14439771 | G5: 0.14455584 | H5: 0.098759045 | I5: 0.21 | J5: 0.28651511 | K5: 0.46999193 | L5: 10.141703 | M5: 68.30523 | N5: -2.0132396 | O5: 6.7461712
B6: ABB INDIA LTD | C6: 0.041244246 | D6: 0.12149798 | E6: 0.20095707 | F6: 0.19998138 | G6: 0.14583465 | H6: 0.07307014 | I6: 1.04 | J6: 0.044920614 | K6: 0.29874474 | L6: 52.273781 | M6: 61.01149 | N6: 1.543865 | O6: 20.701385
B7: ACC LTD | C7: 0.063508927 | D7: 0.071871941 | E7: 0.15149665 | F7: 0.14758414 | G7: 0.11099816 | H7: 0.075660683 | I7: 0.89 | J7: 0.012001138 | K7: 0.068702999 | L7: 23.112222 | M7: 11.735329 | N7: 1.0643306 | O7: 1.9967767
B8: ADANI ENERGY SOLUTIONS LTD | C8: 0.21585966 | D8: -0.030365028 | E8: 0 | F8: 0.059354461 | G8: 0.0095197068 | H8: 0.0073652368 | I8: 0.36 | J8: 1.5560273 | K8: -672.65195 | L8: 1.3808395 | M8: 2295.9321 | N8: -47.403212 | O8: 5.3177615
B9: ADANI ENTERPRISES LTD | C9: 0.12709605 | D9: 0.24349411 | E9: 0.27789693 | F9: 0.16501569 | G9: 0.13172669 | H9: 0.044552174 | I9: 0.55 | J9: 0.87927813 | K9: 5.0673073 | L9: 3.6357609 | M9: 107.55819 | N9: 0.4031927 | O9: 10.011264
B10: ADANI GREEN ENERGY LTD | C10: 0 | D10: 0 | E10: 0 | F10: 0.04422918 | G10: 0.0048191002 | H10: -0.00083313028 | I10: 0.11 | J10: 2.5106129 | K10: 41.543312 | L10: 0.91005016 | M10: 110.47046 | N10: 11.615886 | O10: 18.298363
B11: ADANI PORTS & SPECIAL ECONOMIC ZONE LTD | C11: 0.055273524 | D11: 0.04847162 | E11: -0.018595553 | F11: 0.087839686 | G11: 0.084746588 | H11: 0.034349637 | I11: 0.24 | J11: 1.468425 | K11: 10.186668 | L11: 2.2834278 | M11: 57.565439 | N11: 2.5149985 | O11: 8.4416426
B12: ADANI POWER LTD | C12: 0.14594229 | D12: 0.18677756 | E12: 0.61370628 | F12: 0.10356108 | G12: -0.0054888925 | H12: 0.035233391 | I12: 0.55 | J12: 1.4721055 | K12: -93.983633 | L12: 2.1441064 | M12: 11.6182 | N12: -0.41327703 | O12: 4.229028
B13: ADANI TOTAL GAS LTD | C13: 0.16016358 | D13: 0.18529723 | E13: 0.23040591 | F13: 0.21608012 | G13: 0.19670399 | H13: 0.10510485 | I13: 0.7 | J13: 0.53076887 | K13: 1.5530747 | L13: 9.5618114 | M13: 59.492747 | N13: -131.48324 | O13: 15.835615
B14: ADITYA BIRLA CAPITAL LTD | C14: 1.1492571 | D14: 1.5005678 | E14: 0 | F14: 0.030366537 | G14: 0.034976949 | H14: 0.012094898 | I14: 0.16 | J14: 1.0027578 | K14: 15.902936 | L14: 738.66487 | M14: 13.163099 | N14: 33.891663 | O14: 1.9150765
B15: ALKEM LABORATORIES LTD | C15: 0.084644805 | D15: 0.11422071 | E15: 0.12535318 | F15: 0.17768673 | G15: 0.17383134 | H15: 0.12628916 | I15: 0.78 | J15: 0.13127626 | K15: 0.64724874 | L15: 33.873361 | M15: 26.791453 | N15: 0.83791192 | O15: 4.7383491
B16: AMBUJA CEMENTS LTD | C16: 0.075248702 | D16: 0.066522698 | E16: 0.16611917 | F16: 0.093788068 | G16: 0.073575396 | H16: 0.060028116 | I16: 0.48 | J16: 0.010924864 | K16: 0.10218137 | L16: 24.957476 | M16: 43.413516 | N16: 0.81175009 | O16: 2.7280982
... B204: ZYDUS LIFESCIENCES LTD | C204: 0.079534843 | D204: 0.11616935 | E204: 0.10979991 | F204: 0.14280256 | G204: 0.14710412 | H204: 0.096432496 | I204: 0.71 | J204: 0.3567481 | K204: 2.588669 | L204: 20.421517 | M204: 12.588404 | N204: 0.2277866 | O204: 4.2090206

Sheet Percentile Ranking
B2: Percentile Score
C3: Growth Metrics (0.25) | F3: Return Metrics (0.25) | J3: Leverage Metrics (0.25) | M3: Valuation Metrics (0.25)
A4: # | B4: Company | C4: 10Y Sales CAGR | D4: 10Y EBITDA CAGR | E4: 10Y Net Profit CAGR | F4: 10Y Mean ROCE | G4: 10Y Mean ROE | H4: 10Y Mean ROA | I4: Asset Turnover Ratio - Current | J4: 10Y Debt to Equity Mean | K4: 10Y Debt to EBITDA Mean | L4: 10Y Interest Coverage Ratio Mean | M4: Current EV/EBITDA Ratio | N4: Current PEG Ratio | O4: Current P/B Ratio
B5: 360 ONE WAM LTD | C5: =IFERROR(_xlfn.PERCENTRANK.INC('Master Data'!$C$5:$C$204,'Master Data'!$C5),0) -> 0.276 | D5: =IFERROR(_xlfn.PERCENTRANK.INC('Master Data'!$D$5:$D$204,'Master Data'!$D5),0) -> 0.648 | E5: =IFERROR(_xlfn.PERCENTRANK.INC('Master Data'!$E$5:$E$204,'Master Data'!$E5),0) -> 0.578 | F5: =IFERROR(_xlfn.PERCENTRANK.INC('Master Data'!$F$5:$F$204,'Master Data'!$F5),0) -> 0.513 | G5: =IFERROR(_xlfn.PERCENTRANK.INC('Master Data'!$G$5:$G$204,'Master Data'!$G5),0) -> 0.548 | H5: =IFERROR(_xlfn.PERCENTRANK.INC('Master Data'!$H$5:$H$204,'Master Data'!$H5),0) -> 0.704 | I5: =IFERROR(_xlfn.PERCENTRANK.INC('Master Data'!$I$5:$I$204,'Master Data'!$I5),0) -> 0.226 | J5: =IFERROR(1-_xlfn.PERCENTRANK.INC('Master Data'!$J$5:$J$204,'Master Data'!$J5),0) -> 0.472 | K5: =IFERROR(1-_xlfn.PERCENTRANK.INC('Master Data'!$K$5:$K$204,'Master Data'!$K5),0) -> 0.613 | L5: =IFERROR(_xlfn.PERCENTRANK.INC('Master Data'!$L$5:$L$204,'Master Data'!$L5),0) -> 0.477 | M5: =IFERROR(1-_xlfn.PERCENTRANK.INC('Master Data'!$M$5:$M$204,'Master Data'!$M5),0) -> 0.151 | N5: =IFERROR(1-_xlfn.PERCENTRANK.INC('Master Data'!$N$5:$N$204,'Master Data'!$N5),0) -> 0.834 | O5: =IFERROR(1-_xlfn.PERCENTRANK.INC('Master Data'!$O$5:$O$204,'Master Data'!$O5),0) -> 0.417
B6: ABB INDIA LTD | C6: =IFERROR(_xlfn.PERCENTRANK.INC('Master Data'!$C$5:$C$204,'Master Data'!$C6),0) -> 0.211 | D6: =IFERROR(_xlfn.PERCENTRANK.INC('Master Data'!$D$5:$D$204,'Master Data'!$D6),0) -> 0.608 | E6: =IFERROR(_xlfn.PERCENTRANK.INC('Master Data'!$E$5:$E$204,'Master Data'!$E6),0) -> 0.799 | F6: =IFERROR(_xlfn.PERCENTRANK.INC('Master Data'!$F$5:$F$204,'Master Data'!$F6),0) -> 0.698 | G6: =IFERROR(_xlfn.PERCENTRANK.INC('Master Data'!$G$5:$G$204,'Master Data'!$G6),0) -> 0.553 | H6: =IFERROR(_xlfn.PERCENTRANK.INC('Master Data'!$H$5:$H$204,'Master Data'!$H6),0) -> 0.573 | I6: =IFERROR(_xlfn.PERCENTRANK.INC('Master Data'!$I$5:$I$204,'Master Data'!$I6),0) -> 0.744 | J6: =IFERROR(1-_xlfn.PERCENTRANK.INC('Master Data'!$J$5:$J$204,'Master Data'!$J6),0) -> 0.789 | K6: =IFERROR(1-_xlfn.PERCENTRANK.INC('Master Data'!$K$5:$K$204,'Master Data'!$K6),0) -> 0.668 | L6: =IFERROR(_xlfn.PERCENTRANK.INC('Master Data'!$L$5:$L$204,'Master Data'!$L6),0) -> 0.714 | M6: =IFERROR(1-_xlfn.PERCENTRANK.INC('Master Data'!$M$5:$M$204,'Master Data'!$M6),0) -> 0.181 | N6: =IFERROR(1-_xlfn.PERCENTRANK.INC('Master Data'!$N$5:$N$204,'Master Data'!$N6),0) -> 0.337 | O6: =IFERROR(1-_xlfn.PERCENTRANK.INC('Master Data'!$O$5:$O$204,'Master Data'!$O6),0) -> 0.06
B7: ACC LTD | C7: =IFERROR(_xlfn.PERCENTRANK.INC('Master Data'!$C$5:$C$204,'Master Data'!$C7),0) -> 0.302 | D7: =IFERROR(_xlfn.PERCENTRANK.INC('Master Data'!$D$5:$D$204,'Master Data'!$D7),0) -> 0.362 | E7: =IFERROR(_xlfn.PERCENTRANK.INC('Master Data'!$E$5:$E$204,'Master Data'!$E7),0) -> 0.698 | F7: =IFERROR(_xlfn.PERCENTRANK.INC('Master Data'!$F$5:$F$204,'Master Data'!$F7),0) -> 0.533 | G7: =IFERROR(_xlfn.PERCENTRANK.INC('Master Data'!$G$5:$G$204,'Master Data'!$G7),0) -> 0.347 | H7: =IFERROR(_xlfn.PERCENTRANK.INC('Master Data'!$H$5:$H$204,'Master Data'!$H7),0) -> 0.593 | I7: =IFERROR(_xlfn.PERCENTRANK.INC('Master Data'!$I$5:$I$204,'Master Data'!$I7),0) -> 0.663 | J7: =IFERROR(1-_xlfn.PERCENTRANK.INC('Master Data'!$J$5:$J$204,'Master Data'!$J7),0) -> 0.869 | K7: =IFERROR(1-_xlfn.PERCENTRANK.INC('Master Data'!$K$5:$K$204,'Master Data'!$K7),0) -> 0.814 | L7: =IFERROR(_xlfn.PERCENTRANK.INC('Master Data'!$L$5:$L$204,'Master Data'!$L7),0) -> 0.588 | M7: =IFERROR(1-_xlfn.PERCENTRANK.INC('Master Data'!$M$5:$M$204,'Master Data'!$M7),0) -> 0.864 | N7: =IFERROR(1-_xlfn.PERCENTRANK.INC('Master Data'!$N$5:$N$204,'Master Data'!$N7),0) -> 0.427 | O7: =IFERROR(1-_xlfn.PERCENTRANK.INC('Master Data'!$O$5:$O$204,'Master Data'!$O7),0) -> 0.834
B8: ADANI ENERGY SOLUTIONS LTD | C8: =IFERROR(_xlfn.PERCENTRANK.INC('Master Data'!$C$5:$C$204,'Master Data'!$C8),0) -> 0.93 | D8: =IFERROR(_xlfn.PERCENTRANK.INC('Master Data'!$D$5:$D$204,'Master Data'!$D8),0) -> 0.02 | E8: =IFERROR(_xlfn.PERCENTRANK.INC('Master Data'!$E$5:$E$204,'Master Data'!$E8),0) -> 0.04 | F8: =IFERROR(_xlfn.PERCENTRANK.INC('Master Data'!$F$5:$F$204,'Master Data'!$F8),0) -> 0.176 | G8: =IFERROR(_xlfn.PERCENTRANK.INC('Master Data'!$G$5:$G$204,'Master Data'!$G8),0) -> 0.08 | H8: =IFERROR(_xlfn.PERCENTRANK.INC('Master Data'!$H$5:$H$204,'Master Data'!$H8),0) -> 0.121 | I8: =IFERROR(_xlfn.PERCENTRANK.INC('Master Data'!$I$5:$I$204,'Master Data'!$I8),0) -> 0.327 | J8: =IFERROR(1-_xlfn.PERCENTRANK.INC('Master Data'!$J$5:$J$204,'Master Data'!$J8),0) -> 0.186 | K8: =IFERROR(1-_xlfn.PERCENTRANK.INC('Master Data'!$K$5:$K$204,'Master Data'!$K8),0) -> 1 | L8: =IFERROR(_xlfn.PERCENTRANK.INC('Master Data'!$L$5:$L$204,'Master Data'!$L8),0) -> 0.111 | M8: =IFERROR(1-_xlfn.PERCENTRANK.INC('Master Data'!$M$5:$M$204,'Master Data'!$M8),0) -> 0 | N8: =IFERROR(1-_xlfn.PERCENTRANK.INC('Master Data'!$N$5:$N$204,'Master Data'!$N8),0) -> 0.99 | O8: =IFERROR(1-_xlfn.PERCENTRANK.INC('Master Data'!$O$5:$O$204,'Master Data'!$O8),0) -> 0.528
B9: ADANI ENTERPRISES LTD | C9: =IFERROR(_xlfn.PERCENTRANK.INC('Master Data'!$C$5:$C$204,'Master Data'!$C9),0) -> 0.698 | D9: =IFERROR(_xlfn.PERCENTRANK.INC('Master Data'!$D$5:$D$204,'Master Data'!$D9),0) -> 0.945 | E9: =IFERROR(_xlfn.PERCENTRANK.INC('Master Data'!$E$5:$E$204,'Master Data'!$E9),0) -> 0.93 | F9: =IFERROR(_xlfn.PERCENTRANK.INC('Master Data'!$F$5:$F$204,'Master Data'!$F9),0) -> 0.578 | G9: =IFERROR(_xlfn.PERCENTRANK.INC('Master Data'!$G$5:$G$204,'Master Data'!$G9),0) -> 0.467 | H9: =IFERROR(_xlfn.PERCENTRANK.INC('Master Data'!$H$5:$H$204,'Master Data'!$H9),0) -> 0.397 | I9: =IFERROR(_xlfn.PERCENTRANK.INC('Master Data'!$I$5:$I$204,'Master Data'!$I9),0) -> 0.407 | J9: =IFERROR(1-_xlfn.PERCENTRANK.INC('Master Data'!$J$5:$J$204,'Master Data'!$J9),0) -> 0.266 | K9: =IFERROR(1-_xlfn.PERCENTRANK.INC('Master Data'!$K$5:$K$204,'Master Data'!$K9),0) -> 0.241 | L9: =IFERROR(_xlfn.PERCENTRANK.INC('Master Data'!$L$5:$L$204,'Master Data'!$L9),0) -> 0.307 | M9: =IFERROR(1-_xlfn.PERCENTRANK.INC('Master Data'!$M$5:$M$204,'Master Data'!$M9),0) -> 0.09 | N9: =IFERROR(1-_xlfn.PERCENTRANK.INC('Master Data'!$N$5:$N$204,'Master Data'!$N9),0) -> 0.598 | O9: =IFERROR(1-_xlfn.PERCENTRANK.INC('Master Data'!$O$5:$O$204,'Master Data'!$O9),0) -> 0.281
B10: ADANI GREEN ENERGY LTD | C10: =IFERROR(_xlfn.PERCENTRANK.INC('Master Data'!$C$5:$C$204,'Master Data'!$C10),0) -> 0.03 | D10: =IFERROR(_xlfn.PERCENTRANK.INC('Master Data'!$D$5:$D$204,'Master Data'!$D10),0) -> 0.05 | E10: =IFERROR(_xlfn.PERCENTRANK.INC('Master Data'!$E$5:$E$204,'Master Data'!$E10),0) -> 0.04 | F10: =IFERROR(_xlfn.PERCENTRANK.INC('Master Data'!$F$5:$F$204,'Master Data'!$F10),0) -> 0.075 | G10: =IFERROR(_xlfn.PERCENTRANK.INC('Master Data'!$G$5:$G$204,'Master Data'!$G10),0) -> 0.065 | H10: =IFERROR(_xlfn.PERCENTRANK.INC('Master Data'!$H$5:$H$204,'Master Data'!$H10),0) -> 0.05 | I10: =IFERROR(_xlfn.PERCENTRANK.INC('Master Data'!$I$5:$I$204,'Master Data'!$I10),0) -> 0.131 | J10: =IFERROR(1-_xlfn.PERCENTRANK.INC('Master Data'!$J$5:$J$204,'Master Data'!$J10),0) -> 0.156 | K10: =IFERROR(1-_xlfn.PERCENTRANK.INC('Master Data'!$K$5:$K$204,'Master Data'!$K10),0) -> 0.015 | L10: =IFERROR(_xlfn.PERCENTRANK.INC('Master Data'!$L$5:$L$204,'Master Data'!$L10),0) -> 0.04 | M10: =IFERROR(1-_xlfn.PERCENTRANK.INC('Master Data'!$M$5:$M$204,'Master Data'!$M10),0) -> 0.085 | N10: =IFERROR(1-_xlfn.PERCENTRANK.INC('Master Data'!$N$5:$N$204,'Master Data'!$N10),0) -> 0.05 | O10: =IFERROR(1-_xlfn.PERCENTRANK.INC('Master Data'!$O$5:$O$204,'Master Data'!$O10),0) -> 0.08
B11: ADANI PORTS & SPECIAL ECONOMIC ZONE LTD | C11: =IFERROR(_xlfn.PERCENTRANK.INC('Master Data'!$C$5:$C$204,'Master Data'!$C11),0) -> 0.261 | D11: =IFERROR(_xlfn.PERCENTRANK.INC('Master Data'!$D$5:$D$204,'Master Data'!$D11),0) -> 0.302 | E11: =IFERROR(_xlfn.PERCENTRANK.INC('Master Data'!$E$5:$E$204,'Master Data'!$E11),0) -> 0.025 | F11: =IFERROR(_xlfn.PERCENTRANK.INC('Master Data'!$F$5:$F$204,'Master Data'!$F11),0) -> 0.307 | G11: =IFERROR(_xlfn.PERCENTRANK.INC('Master Data'!$G$5:$G$204,'Master Data'!$G11),0) -> 0.256 | H11: =IFERROR(_xlfn.PERCENTRANK.INC('Master Data'!$H$5:$H$204,'Master Data'!$H11),0) -> 0.322 | I11: =IFERROR(_xlfn.PERCENTRANK.INC('Master Data'!$I$5:$I$204,'Master Data'!$I11),0) -> 0.246 | J11: =IFERROR(1-_xlfn.PERCENTRANK.INC('Master Data'!$J$5:$J$204,'Master Data'!$J11),0) -> 0.196 | K11: =IFERROR(1-_xlfn.PERCENTRANK.INC('Master Data'!$K$5:$K$204,'Master Data'!$K11),0) -> 0.141 | L11: =IFERROR(_xlfn.PERCENTRANK.INC('Master Data'!$L$5:$L$204,'Master Data'!$L11),0) -> 0.236 | M11: =IFERROR(1-_xlfn.PERCENTRANK.INC('Master Data'!$M$5:$M$204,'Master Data'!$M11),0) -> 0.211 | N11: =IFERROR(1-_xlfn.PERCENTRANK.INC('Master Data'!$N$5:$N$204,'Master Data'!$N11),0) -> 0.236 | O11: =IFERROR(1-_xlfn.PERCENTRANK.INC('Master Data'!$O$5:$O$204,'Master Data'!$O11),0) -> 0.342
B12: ADANI POWER LTD | C12: =IFERROR(_xlfn.PERCENTRANK.INC('Master Data'!$C$5:$C$204,'Master Data'!$C12),0) -> 0.794 | D12: =IFERROR(_xlfn.PERCENTRANK.INC('Master Data'!$D$5:$D$204,'Master Data'!$D12),0) -> 0.844 | E12: =IFERROR(_xlfn.PERCENTRANK.INC('Master Data'!$E$5:$E$204,'Master Data'!$E12),0) -> 1 | F12: =IFERROR(_xlfn.PERCENTRANK.INC('Master Data'!$F$5:$F$204,'Master Data'!$F12),0) -> 0.352 | G12: =IFERROR(_xlfn.PERCENTRANK.INC('Master Data'!$G$5:$G$204,'Master Data'!$G12),0) -> 0.05 | H12: =IFERROR(_xlfn.PERCENTRANK.INC('Master Data'!$H$5:$H$204,'Master Data'!$H12),0) -> 0.332 | I12: =IFERROR(_xlfn.PERCENTRANK.INC('Master Data'!$I$5:$I$204,'Master Data'!$I12),0) -> 0.407 | J12: =IFERROR(1-_xlfn.PERCENTRANK.INC('Master Data'!$J$5:$J$204,'Master Data'!$J12),0) -> 0.191 | K12: =IFERROR(1-_xlfn.PERCENTRANK.INC('Master Data'!$K$5:$K$204,'Master Data'!$K12),0) -> 0.995 | L12: =IFERROR(_xlfn.PERCENTRANK.INC('Master Data'!$L$5:$L$204,'Master Data'!$L12),0) -> 0.216 | M12: =IFERROR(1-_xlfn.PERCENTRANK.INC('Master Data'!$M$5:$M$204,'Master Data'!$M12),0) -> 0.874 | N12: =IFERROR(1-_xlfn.PERCENTRANK.INC('Master Data'!$N$5:$N$204,'Master Data'!$N12),0) -> 0.769 | O12: =IFERROR(1-_xlfn.PERCENTRANK.INC('Master Data'!$O$5:$O$204,'Master Data'!$O12),0) -> 0.623
B13: ADANI TOTAL GAS LTD | C13: =IFERROR(_xlfn.PERCENTRANK.INC('Master Data'!$C$5:$C$204,'Master Data'!$C13),0) -> 0.859 | D13: =IFERROR(_xlfn.PERCENTRANK.INC('Master Data'!$D$5:$D$204,'Master Data'!$D13),0) -> 0.829 | E13: =IFERROR(_xlfn.PERCENTRANK.INC('Master Data'!$E$5:$E$204,'Master Data'!$E13),0) -> 0.869 | F13: =IFERROR(_xlfn.PERCENTRANK.INC('Master Data'!$F$5:$F$204,'Master Data'!$F13),0) -> 0.719 | G13: =IFERROR(_xlfn.PERCENTRANK.INC('Master Data'!$G$5:$G$204,'Master Data'!$G13),0) -> 0.779 | H13: =IFERROR(_xlfn.PERCENTRANK.INC('Master Data'!$H$5:$H$204,'Master Data'!$H13),0) -> 0.744 | I13: =IFERROR(_xlfn.PERCENTRANK.INC('Master Data'!$I$5:$I$204,'Master Data'!$I13),0) -> 0.513 | J13: =IFERROR(1-_xlfn.PERCENTRANK.INC('Master Data'!$J$5:$J$204,'Master Data'!$J13),0) -> 0.357 | K13: =IFERROR(1-_xlfn.PERCENTRANK.INC('Master Data'!$K$5:$K$204,'Master Data'!$K13),0) -> 0.452 | L13: =IFERROR(_xlfn.PERCENTRANK.INC('Master Data'!$L$5:$L$204,'Master Data'!$L13),0) -> 0.462 | M13: =IFERROR(1-_xlfn.PERCENTRANK.INC('Master Data'!$M$5:$M$204,'Master Data'!$M13),0) -> 0.191 | N13: =IFERROR(1-_xlfn.PERCENTRANK.INC('Master Data'!$N$5:$N$204,'Master Data'!$N13),0) -> 1 | O13: =IFERROR(1-_xlfn.PERCENTRANK.INC('Master Data'!$O$5:$O$204,'Master Data'!$O13),0) -> 0.116
B14: ADITYA BIRLA CAPITAL LTD | C14: =IFERROR(_xlfn.PERCENTRANK.INC('Master Data'!$C$5:$C$204,'Master Data'!$C14),0) -> 1 | D14: =IFERROR(_xlfn.PERCENTRANK.INC('Master Data'!$D$5:$D$204,'Master Data'!$D14),0) -> 1 | E14: =IFERROR(_xlfn.PERCENTRANK.INC('Master Data'!$E$5:$E$204,'Master Data'!$E14),0) -> 0.04 | F14: =IFERROR(_xlfn.PERCENTRANK.INC('Master Data'!$F$5:$F$204,'Master Data'!$F14),0) -> 0.055 | G14: =IFERROR(_xlfn.PERCENTRANK.INC('Master Data'!$G$5:$G$204,'Master Data'!$G14),0) -> 0.116 | H14: =IFERROR(_xlfn.PERCENTRANK.INC('Master Data'!$H$5:$H$204,'Master Data'!$H14),0) -> 0.156 | I14: =IFERROR(_xlfn.PERCENTRANK.INC('Master Data'!$I$5:$I$204,'Master Data'!$I14),0) -> 0.186 | J14: =IFERROR(1-_xlfn.PERCENTRANK.INC('Master Data'!$J$5:$J$204,'Master Data'!$J14),0) -> 0.236 | K14: =IFERROR(1-_xlfn.PERCENTRANK.INC('Master Data'!$K$5:$K$204,'Master Data'!$K14),0) -> 0.095 | L14: =IFERROR(_xlfn.PERCENTRANK.INC('Master Data'!$L$5:$L$204,'Master Data'!$L14),0) -> 0.965 | M14: =IFERROR(1-_xlfn.PERCENTRANK.INC('Master Data'!$M$5:$M$204,'Master Data'!$M14),0) -> 0.814 | N14: =IFERROR(1-_xlfn.PERCENTRANK.INC('Master Data'!$N$5:$N$204,'Master Data'!$N14),0) -> 0.015 | O14: =IFERROR(1-_xlfn.PERCENTRANK.INC('Master Data'!$O$5:$O$204,'Master Data'!$O14),0) -> 0.844
B15: ALKEM LABORATORIES LTD | C15: =IFERROR(_xlfn.PERCENTRANK.INC('Master Data'!$C$5:$C$204,'Master Data'!$C15),0) -> 0.447 | D15: =IFERROR(_xlfn.PERCENTRANK.INC('Master Data'!$D$5:$D$204,'Master Data'!$D15),0) -> 0.568 | E15: =IFERROR(_xlfn.PERCENTRANK.INC('Master Data'!$E$5:$E$204,'Master Data'!$E15),0) -> 0.583 | F15: =IFERROR(_xlfn.PERCENTRANK.INC('Master Data'!$F$5:$F$204,'Master Data'!$F15),0) -> 0.623 | G15: =IFERROR(_xlfn.PERCENTRANK.INC('Master Data'!$G$5:$G$204,'Master Data'!$G15),0) -> 0.683 | H15: =IFERROR(_xlfn.PERCENTRANK.INC('Master Data'!$H$5:$H$204,'Master Data'!$H15),0) -> 0.809 | I15: =IFERROR(_xlfn.PERCENTRANK.INC('Master Data'!$I$5:$I$204,'Master Data'!$I15),0) -> 0.578 | J15: =IFERROR(1-_xlfn.PERCENTRANK.INC('Master Data'!$J$5:$J$204,'Master Data'!$J15),0) -> 0.588 | K15: =IFERROR(1-_xlfn.PERCENTRANK.INC('Master Data'!$K$5:$K$204,'Master Data'!$K15),0) -> 0.548 | L15: =IFERROR(_xlfn.PERCENTRANK.INC('Master Data'!$L$5:$L$204,'Master Data'!$L15),0) -> 0.658 | M15: =IFERROR(1-_xlfn.PERCENTRANK.INC('Master Data'!$M$5:$M$204,'Master Data'!$M15),0) -> 0.497 | N15: =IFERROR(1-_xlfn.PERCENTRANK.INC('Master Data'!$N$5:$N$204,'Master Data'!$N15),0) -> 0.467 | O15: =IFERROR(1-_xlfn.PERCENTRANK.INC('Master Data'!$O$5:$O$204,'Master Data'!$O15),0) -> 0.583
B16: AMBUJA CEMENTS LTD | C16: =IFERROR(_xlfn.PERCENTRANK.INC('Master Data'!$C$5:$C$204,'Master Data'!$C16),0) -> 0.367 | D16: =IFERROR(_xlfn.PERCENTRANK.INC('Master Data'!$D$5:$D$204,'Master Data'!$D16),0) -> 0.337 | E16: =IFERROR(_xlfn.PERCENTRANK.INC('Master Data'!$E$5:$E$204,'Master Data'!$E16),0) -> 0.719 | F16: =IFERROR(_xlfn.PERCENTRANK.INC('Master Data'!$F$5:$F$204,'Master Data'!$F16),0) -> 0.327 | G16: =IFERROR(_xlfn.PERCENTRANK.INC('Master Data'!$G$5:$G$204,'Master Data'!$G16),0) -> 0.221 | H16: =IFERROR(_xlfn.PERCENTRANK.INC('Master Data'!$H$5:$H$204,'Master Data'!$H16),0) -> 0.482 | I16: =IFERROR(_xlfn.PERCENTRANK.INC('Master Data'!$I$5:$I$204,'Master Data'!$I16),0) -> 0.372 | J16: =IFERROR(1-_xlfn.PERCENTRANK.INC('Master Data'!$J$5:$J$204,'Master Data'!$J16),0) -> 0.884 | K16: =IFERROR(1-_xlfn.PERCENTRANK.INC('Master Data'!$K$5:$K$204,'Master Data'!$K16),0) -> 0.784 | L16: =IFERROR(_xlfn.PERCENTRANK.INC('Master Data'!$L$5:$L$204,'Master Data'!$L16),0) -> 0.603 | M16: =IFERROR(1-_xlfn.PERCENTRANK.INC('Master Data'!$M$5:$M$204,'Master Data'!$M16),0) -> 0.322 | N16: =IFERROR(1-_xlfn.PERCENTRANK.INC('Master Data'!$N$5:$N$204,'Master Data'!$N16),0) -> 0.472 | O16: =IFERROR(1-_xlfn.PERCENTRANK.INC('Master Data'!$O$5:$O$204,'Master Data'!$O16),0) -> 0.774
... B204: ZYDUS LIFESCIENCES LTD | C204: =IFERROR(_xlfn.PERCENTRANK.INC('Master Data'!$C$5:$C$204,'Master Data'!$C204),0) -> 0.387 | D204: =IFERROR(_xlfn.PERCENTRANK.INC('Master Data'!$D$5:$D$204,'Master Data'!$D204),0) -> 0.573 | E204: =IFERROR(_xlfn.PERCENTRANK.INC('Master Data'!$E$5:$E$204,'Master Data'!$E204),0) -> 0.538 | F204: =IFERROR(_xlfn.PERCENTRANK.INC('Master Data'!$F$5:$F$204,'Master Data'!$F204),0) -> 0.503 | G204: =IFERROR(_xlfn.PERCENTRANK.INC('Master Data'!$G$5:$G$204,'Master Data'!$G204),0) -> 0.563 | H204: =IFERROR(_xlfn.PERCENTRANK.INC('Master Data'!$H$5:$H$204,'Master Data'!$H204),0) -> 0.698 | I204: =IFERROR(_xlfn.PERCENTRANK.INC('Master Data'!$I$5:$I$204,'Master Data'!$I204),0) -> 0.528 | J204: =IFERROR(1-_xlfn.PERCENTRANK.INC('Master Data'!$J$5:$J$204,'Master Data'!$J204),0) -> 0.437 | K204: =IFERROR(1-_xlfn.PERCENTRANK.INC('Master Data'!$K$5:$K$204,'Master Data'!$K204),0) -> 0.352 | L204: =IFERROR(_xlfn.PERCENTRANK.INC('Master Data'!$L$5:$L$204,'Master Data'!$L204),0) -> 0.573 | M204: =IFERROR(1-_xlfn.PERCENTRANK.INC('Master Data'!$M$5:$M$204,'Master Data'!$M204),0) -> 0.839 | N204: =IFERROR(1-_xlfn.PERCENTRANK.INC('Master Data'!$N$5:$N$204,'Master Data'!$N204),0) -> 0.648 | O204: =IFERROR(1-_xlfn.PERCENTRANK.INC('Master Data'!$O$5:$O$204,'Master Data'!$O204),0) -> 0.633
